2019-12-07 06:43:38,426 ERROR: Exception on /translate [POST] [in c:\users\chirag~1\desktop\microb~1\venv\lib\site-packages\flask\app.py:1891]
Traceback (most recent call last):
  File "c:\users\chirag~1\desktop\microb~1\venv\lib\site-packages\flask\app.py", line 2446, in wsgi_app
    response = self.full_dispatch_request()
  File "c:\users\chirag~1\desktop\microb~1\venv\lib\site-packages\flask\app.py", line 1951, in full_dispatch_request
    rv = self.handle_user_exception(e)
  File "c:\users\chirag~1\desktop\microb~1\venv\lib\site-packages\flask\app.py", line 1820, in handle_user_exception
    reraise(exc_type, exc_value, tb)
  File "c:\users\chirag~1\desktop\microb~1\venv\lib\site-packages\flask\_compat.py", line 39, in reraise
    raise value
  File "c:\users\chirag~1\desktop\microb~1\venv\lib\site-packages\flask\app.py", line 1949, in full_dispatch_request
    rv = self.dispatch_request()
  File "c:\users\chirag~1\desktop\microb~1\venv\lib\site-packages\flask\app.py", line 1935, in dispatch_request
    return self.view_functions[rule.endpoint](**req.view_args)
  File "c:\users\chirag~1\desktop\microb~1\venv\lib\site-packages\flask_login\utils.py", line 261, in decorated_view
    return func(*args, **kwargs)
  File "C:\Users\Chirag Kushwaha\Desktop\microblog\app\routes.py", line 201, in translate_text
    data=data['text']
TypeError: string indices must be integers
2019-12-07 06:45:02,322 INFO: Microblog startup [in C:\Users\Chirag Kushwaha\Desktop\microblog\app\__init__.py:52]
2019-12-07 06:45:10,510 ERROR: Exception on /translate [POST] [in c:\users\chirag~1\desktop\microb~1\venv\lib\site-packages\flask\app.py:1891]
Traceback (most recent call last):
  File "c:\users\chirag~1\desktop\microb~1\venv\lib\site-packages\flask\app.py", line 2446, in wsgi_app
    response = self.full_dispatch_request()
  File "c:\users\chirag~1\desktop\microb~1\venv\lib\site-packages\flask\app.py", line 1951, in full_dispatch_request
    rv = self.handle_user_exception(e)
  File "c:\users\chirag~1\desktop\microb~1\venv\lib\site-packages\flask\app.py", line 1820, in handle_user_exception
    reraise(exc_type, exc_value, tb)
  File "c:\users\chirag~1\desktop\microb~1\venv\lib\site-packages\flask\_compat.py", line 39, in reraise
    raise value
  File "c:\users\chirag~1\desktop\microb~1\venv\lib\site-packages\flask\app.py", line 1949, in full_dispatch_request
    rv = self.dispatch_request()
  File "c:\users\chirag~1\desktop\microb~1\venv\lib\site-packages\flask\app.py", line 1935, in dispatch_request
    return self.view_functions[rule.endpoint](**req.view_args)
  File "c:\users\chirag~1\desktop\microb~1\venv\lib\site-packages\flask_login\utils.py", line 261, in decorated_view
    return func(*args, **kwargs)
  File "C:\Users\Chirag Kushwaha\Desktop\microblog\app\routes.py", line 202, in translate_text
    data=data['text']
TypeError: string indices must be integers
2019-12-07 06:45:37,402 INFO: Microblog startup [in C:\Users\Chirag Kushwaha\Desktop\microblog\app\__init__.py:52]
2019-12-07 06:47:49,588 INFO: Microblog startup [in C:\Users\Chirag Kushwaha\Desktop\microblog\app\__init__.py:52]
2019-12-07 06:48:10,514 INFO: Microblog startup [in C:\Users\Chirag Kushwaha\Desktop\microblog\app\__init__.py:52]
2019-12-07 06:49:05,602 INFO: Microblog startup [in C:\Users\Chirag Kushwaha\Desktop\microblog\app\__init__.py:52]
2019-12-07 06:52:39,323 INFO: Microblog startup [in C:\Users\Chirag Kushwaha\Desktop\microblog\app\__init__.py:52]
2019-12-07 06:55:46,309 INFO: Microblog startup [in C:\Users\Chirag Kushwaha\Desktop\microblog\app\__init__.py:52]
2019-12-07 06:57:21,276 INFO: Microblog startup [in C:\Users\Chirag Kushwaha\Desktop\microblog\app\__init__.py:52]
2019-12-07 06:58:11,098 INFO: Microblog startup [in C:\Users\Chirag Kushwaha\Desktop\microblog\app\__init__.py:52]
2019-12-07 07:02:52,880 INFO: Microblog startup [in C:\Users\Chirag Kushwaha\Desktop\microblog\app\__init__.py:52]
2019-12-07 07:03:04,295 INFO: Microblog startup [in C:\Users\Chirag Kushwaha\Desktop\microblog\app\__init__.py:52]
2019-12-07 10:00:21,421 INFO: Microblog startup [in C:\Users\Chirag Kushwaha\Desktop\microblog\app\__init__.py:77]
2019-12-07 13:24:34,292 INFO: Microblog startup [in C:\Users\Chirag Kushwaha\Desktop\microblog\app\__init__.py:80]
2019-12-07 13:48:56,440 INFO: Microblog startup [in C:\Users\Chirag Kushwaha\Desktop\microblog\app\__init__.py:80]
2019-12-08 10:51:13,064 INFO: Microblog startup [in C:\Users\Chirag Kushwaha\Desktop\microblog\app\__init__.py:89]
2019-12-08 10:51:30,920 INFO: Microblog startup [in C:\Users\Chirag Kushwaha\Desktop\microblog\app\__init__.py:89]
2019-12-08 10:58:15,537 INFO: Microblog startup [in C:\Users\Chirag Kushwaha\Desktop\microblog\app\__init__.py:89]
2019-12-08 10:58:39,158 ERROR: Exception on /auth/login [POST] [in c:\users\chirag~1\desktop\microb~1\venv\lib\site-packages\flask\app.py:1761]
Traceback (most recent call last):
  File "c:\users\chirag~1\desktop\microb~1\venv\lib\site-packages\sqlalchemy\engine\base.py", line 1182, in _execute_context
    context)
  File "c:\users\chirag~1\desktop\microb~1\venv\lib\site-packages\sqlalchemy\engine\default.py", line 470, in do_execute
    cursor.execute(statement, parameters)
sqlite3.OperationalError: no such column: user.token

The above exception was the direct cause of the following exception:

Traceback (most recent call last):
  File "c:\users\chirag~1\desktop\microb~1\venv\lib\site-packages\flask\app.py", line 2292, in wsgi_app
    response = self.full_dispatch_request()
  File "c:\users\chirag~1\desktop\microb~1\venv\lib\site-packages\flask\app.py", line 1815, in full_dispatch_request
    rv = self.handle_user_exception(e)
  File "c:\users\chirag~1\desktop\microb~1\venv\lib\site-packages\flask\app.py", line 1718, in handle_user_exception
    reraise(exc_type, exc_value, tb)
  File "c:\users\chirag~1\desktop\microb~1\venv\lib\site-packages\flask\_compat.py", line 35, in reraise
    raise value
  File "c:\users\chirag~1\desktop\microb~1\venv\lib\site-packages\flask\app.py", line 1813, in full_dispatch_request
    rv = self.dispatch_request()
  File "c:\users\chirag~1\desktop\microb~1\venv\lib\site-packages\flask\app.py", line 1799, in dispatch_request
    return self.view_functions[rule.endpoint](**req.view_args)
  File "C:\Users\Chirag Kushwaha\Desktop\microblog\app\auth\routes.py", line 19, in login
    user = User.query.filter_by(username=form.username.data).first()
  File "c:\users\chirag~1\desktop\microb~1\venv\lib\site-packages\sqlalchemy\orm\query.py", line 2755, in first
    ret = list(self[0:1])
  File "c:\users\chirag~1\desktop\microb~1\venv\lib\site-packages\sqlalchemy\orm\query.py", line 2547, in __getitem__
    return list(res)
  File "c:\users\chirag~1\desktop\microb~1\venv\lib\site-packages\sqlalchemy\orm\query.py", line 2855, in __iter__
    return self._execute_and_instances(context)
  File "c:\users\chirag~1\desktop\microb~1\venv\lib\site-packages\sqlalchemy\orm\query.py", line 2878, in _execute_and_instances
    result = conn.execute(querycontext.statement, self._params)
  File "c:\users\chirag~1\desktop\microb~1\venv\lib\site-packages\sqlalchemy\engine\base.py", line 945, in execute
    return meth(self, multiparams, params)
  File "c:\users\chirag~1\desktop\microb~1\venv\lib\site-packages\sqlalchemy\sql\elements.py", line 263, in _execute_on_connection
    return connection._execute_clauseelement(self, multiparams, params)
  File "c:\users\chirag~1\desktop\microb~1\venv\lib\site-packages\sqlalchemy\engine\base.py", line 1053, in _execute_clauseelement
    compiled_sql, distilled_params
  File "c:\users\chirag~1\desktop\microb~1\venv\lib\site-packages\sqlalchemy\engine\base.py", line 1189, in _execute_context
    context)
  File "c:\users\chirag~1\desktop\microb~1\venv\lib\site-packages\sqlalchemy\engine\base.py", line 1402, in _handle_dbapi_exception
    exc_info
  File "c:\users\chirag~1\desktop\microb~1\venv\lib\site-packages\sqlalchemy\util\compat.py", line 203, in raise_from_cause
    reraise(type(exception), exception, tb=exc_tb, cause=cause)
  File "c:\users\chirag~1\desktop\microb~1\venv\lib\site-packages\sqlalchemy\util\compat.py", line 186, in reraise
    raise value.with_traceback(tb)
  File "c:\users\chirag~1\desktop\microb~1\venv\lib\site-packages\sqlalchemy\engine\base.py", line 1182, in _execute_context
    context)
  File "c:\users\chirag~1\desktop\microb~1\venv\lib\site-packages\sqlalchemy\engine\default.py", line 470, in do_execute
    cursor.execute(statement, parameters)
sqlalchemy.exc.OperationalError: (sqlite3.OperationalError) no such column: user.token [SQL: 'SELECT user.id AS user_id, user.username AS user_username, user.email AS user_email, user.password_hash AS user_password_hash, user.about_me AS user_about_me, user.last_seen AS user_last_seen, user.token AS user_token, user.token_expiration AS user_token_expiration, user.last_message_read_time AS user_last_message_read_time \nFROM user \nWHERE user.username = ?\n LIMIT ? OFFSET ?'] [parameters: ('Chirag', 1, 0)]
